<?xml version="1.0" ?>

<robot name="wheely_robot" xmlns:xacro="http://www.ros.org/wiki/xacro">

<link name="robot_base">
    <visual>
        <geometry>
            <box size="1.0 1.0 0.2"/>
        </geometry>
        <material name="orange"/>
    </visual>
    <collision>
        <geometry>
            <box size="1.0 1.0 0.2"/>
        </geometry>
  </collision>
  <mass>0.1</mass>
  <inertial>
    <origin xyz="0 0 0.5" rpy="0 0 0"/>
    <mass value="1"/>
    <inertia ixx="100"  ixy="0"  ixz="0" iyy="100" iyz="0" izz="100" />
  </inertial>
</link>

<link name="left_wheel">
    <visual>
        <geometry>
            <cylinder length="0.2" radius="0.2"/>
        </geometry>
    </visual>
    <collision>
        <geometry>
            <cylinder length="0.2" radius="0.2"/>
        </geometry>
    </collision>
    <mass>0.1</mass>
  <inertial>
    <origin xyz="0 0 0.5" rpy="0 0 0"/>
    <mass value="1"/>
    <inertia ixx="100"  ixy="0"  ixz="0" iyy="100" iyz="0" izz="100" />
  </inertial>
</link>

<link name="right_wheel">
    <visual>
        <geometry>
            <cylinder length="0.2" radius="0.2"/>
        </geometry>
    </visual>
    <collision>
        <geometry>
            <cylinder length="0.2" radius="0.2"/>
        </geometry>
    </collision>
    <mass>0.1</mass>
  <inertial>
    <origin xyz="0 0 0.5" rpy="0 0 0"/>
    <mass value="1"/>
    <inertia ixx="100"  ixy="0"  ixz="0" iyy="100" iyz="0" izz="100" />
  </inertial>
</link>

<joint name="base_to_lwheel" type="continuous">
  <parent link="robot_base"/>
  <child link="left_wheel"/>
  <origin xyz="0.6 0 0" rpy="0 1.57079632679 0"/>
  <axis xyz="0 0 1"/>
</joint>

<joint name="base_to_rwheel" type="continuous">
  <parent link="robot_base"/>
  <child link="right_wheel"/>
  <origin xyz="-0.6 0 0" rpy="0 1.57079632679 0"/>
  <axis xyz="0 0 1"/>
</joint>

<gazebo reference="right_wheel">
<material>Gazebo/Blue</material>
</gazebo>

<xacro:include filename="$(find my_robot)/urdf/lidar.xacro"/>
<joint name="lidarGlue" type="fixed">
  <parent link="robot_base"/>
  <child link="laz_base"/>
  <origin xyz="0 0 ${1/2}"/>
</joint>

</robot>

